Traceback (most recent call last):
  File "/Users/kkagawa/localdoc/github/Class/.venv/lib/python3.13/site-packages/jupyter_core/utils/__init__.py", line 154, in wrapped
    asyncio.get_running_loop()
    ~~~~~~~~~~~~~~~~~~~~~~~~^^
RuntimeError: no running event loop

During handling of the above exception, another exception occurred:

Traceback (most recent call last):
  File "/Users/kkagawa/localdoc/github/Class/.venv/lib/python3.13/site-packages/jupyter_cache/executors/utils.py", line 58, in single_nb_execution
    executenb(
    ~~~~~~~~~^
        nb,
        ^^^
    ...<4 lines>...
        **kwargs,
        ^^^^^^^^^
    )
    ^
  File "/Users/kkagawa/localdoc/github/Class/.venv/lib/python3.13/site-packages/nbclient/client.py", line 1319, in execute
    return NotebookClient(nb=nb, resources=resources, km=km, **kwargs).execute()
           ~~~~~~~~~~~~~~~~~~~~~~~~~~~~~~~~~~~~~~~~~~~~~~~~~~~~~~~~~~~~~~~~~~~^^
  File "/Users/kkagawa/localdoc/github/Class/.venv/lib/python3.13/site-packages/jupyter_core/utils/__init__.py", line 158, in wrapped
    return loop.run_until_complete(inner)
           ~~~~~~~~~~~~~~~~~~~~~~~^^^^^^^
  File "/opt/homebrew/Cellar/python@3.13/3.13.2/Frameworks/Python.framework/Versions/3.13/lib/python3.13/asyncio/base_events.py", line 725, in run_until_complete
    return future.result()
           ~~~~~~~~~~~~~^^
  File "/Users/kkagawa/localdoc/github/Class/.venv/lib/python3.13/site-packages/nbclient/client.py", line 709, in async_execute
    await self.async_execute_cell(
        cell, index, execution_count=self.code_cells_executed + 1
    )
  File "/Users/kkagawa/localdoc/github/Class/.venv/lib/python3.13/site-packages/nbclient/client.py", line 1062, in async_execute_cell
    await self._check_raise_for_error(cell, cell_index, exec_reply)
  File "/Users/kkagawa/localdoc/github/Class/.venv/lib/python3.13/site-packages/nbclient/client.py", line 918, in _check_raise_for_error
    raise CellExecutionError.from_cell_and_msg(cell, exec_reply_content)
nbclient.exceptions.CellExecutionError: An error occurred while executing the following cell:
------------------
import matplotlib.pyplot as plt
from matplotlib.patches import Rectangle
from matplotlib import rcParams

rcParams['font.family'] = 'Hiragino Sans'  # 適宜ご利用環境の日本語フォント名に変更してください

# 描画サイズ
fig, ax = plt.subplots(figsize=(8,6))

# 中央のCPU（制御装置＋演算装置）
ax.add_patch(Rectangle((3,3.5), 2, 1, edgecolor="black", facecolor="#f2f2f2"))
ax.text(4, 4, "制御装置", ha="center", va="center", fontsize=12)
ax.add_patch(Rectangle((3,2), 2, 1, edgecolor="black", facecolor="#f2f2f2"))
ax.text(4, 2.5, "演算装置", ha="center", va="center", fontsize=12)
ax.text(4, 4.8, "CPU", ha="center", va="bottom", fontsize=13, fontweight="bold")

# 記憶装置
ax.add_patch(Rectangle((0.5,3), 2, 1.5, edgecolor="black", facecolor="#d9eaf7"))
ax.text(1.5, 3.75, "記憶装置", ha="center", va="center", fontsize=12)

# 入力装置
ax.add_patch(Rectangle((3,6), 2, 1, edgecolor="black", facecolor="#dff0d8"))
ax.text(4, 6.5, "入力装置", ha="center", va="center", fontsize=12)

# 出力装置
ax.add_patch(Rectangle((3,0.5), 2, 1, edgecolor="black", facecolor="#f9e2d2"))
ax.text(4, 1, "出力装置", ha="center", va="center", fontsize=12)

# 矢印
arrow_args = dict(arrowstyle="->", color="black", lw=1.5)
ax.annotate("", xy=(3,4.25), xytext=(2.5,4.25), arrowprops=arrow_args) # CPU→記憶装置
ax.annotate("", xy=(2.5,4.25), xytext=(3,4.25), arrowprops=arrow_args) # 記憶装置→CPU

ax.annotate("", xy=(4,6), xytext=(4,5), arrowprops=arrow_args) # 入力→CPU
ax.annotate("", xy=(4,5), xytext=(4,6), arrowprops=arrow_args) # CPU→入力

ax.annotate("", xy=(4,2), xytext=(4,1.5), arrowprops=arrow_args) # CPU→出力
ax.annotate("", xy=(4,1.5), xytext=(4,2), arrowprops=arrow_args) # 出力→CPU

# 軸非表示
ax.set_xlim(0,7)
ax.set_ylim(0,8)
ax.axis("off")

plt.show()

------------------


[31m---------------------------------------------------------------------------[39m
[31mModuleNotFoundError[39m                       Traceback (most recent call last)
[36mCell[39m[36m [39m[32mIn[1][39m[32m, line 1[39m
[32m----> [39m[32m1[39m [38;5;28;01mimport[39;00m[38;5;250m [39m[34;01mmatplotlib[39;00m[34;01m.[39;00m[34;01mpyplot[39;00m[38;5;250m [39m[38;5;28;01mas[39;00m[38;5;250m [39m[34;01mplt[39;00m
[32m      2[39m [38;5;28;01mfrom[39;00m[38;5;250m [39m[34;01mmatplotlib[39;00m[34;01m.[39;00m[34;01mpatches[39;00m[38;5;250m [39m[38;5;28;01mimport[39;00m Rectangle
[32m      3[39m [38;5;28;01mfrom[39;00m[38;5;250m [39m[34;01mmatplotlib[39;00m[38;5;250m [39m[38;5;28;01mimport[39;00m rcParams

[31mModuleNotFoundError[39m: No module named 'matplotlib'

